I'm sorry, but an uncaught exception occurred.

While running game code:
  File "game/script.rpy", line 276, in script
    $ update_scores(10, 10, 5, 0, 0)
  File "game/script.rpy", line 276, in <module>
    $ update_scores(10, 10, 5, 0, 0)
  File "game/script.rpy", line 1111, in update_scores
    people_score += company_stats[0]
UnboundLocalError: local variable 'people_score' referenced before assignment

-- Full Traceback ------------------------------------------------------------

Full traceback:
  File "game/script.rpy", line 276, in script
    $ update_scores(10, 10, 5, 0, 0)
  File "/Users/rhythm0708/Desktop/renpy-8.3.7-sdk/renpy/ast.py", line 834, in execute
    renpy.python.py_exec_bytecode(self.code.bytecode, self.hide, store=self.store)
  File "/Users/rhythm0708/Desktop/renpy-8.3.7-sdk/renpy/python.py", line 1187, in py_exec_bytecode
    exec(bytecode, globals, locals)
  File "game/script.rpy", line 276, in <module>
    $ update_scores(10, 10, 5, 0, 0)
  File "game/script.rpy", line 1111, in update_scores
    people_score += company_stats[0]
UnboundLocalError: local variable 'people_score' referenced before assignment

macOS-10.16-x86_64-i386-64bit x86_64
Ren'Py 8.3.7.25031702
AI Hiring Edition 1.0
Thu Jul 10 22:05:06 2025
